10
UNKNOWN_ERROR - Fri May 13 17:24:50 2016 - 
10
Traceback (most recent call last):
  File "./manage.py", line 10, in <module>
    execute_from_command_line(sys.argv)
  File "/usr/local/lib/python2.7/dist-packages/django/core/management/__init__.py", line 353, in execute_from_command_line
    utility.execute()
  File "/usr/local/lib/python2.7/dist-packages/django/core/management/__init__.py", line 345, in execute
    self.fetch_command(subcommand).run_from_argv(self.argv)
  File "/usr/local/lib/python2.7/dist-packages/django/core/management/base.py", line 348, in run_from_argv
    self.execute(*args, **cmd_options)
  File "/usr/local/lib/python2.7/dist-packages/django/core/management/base.py", line 399, in execute
    output = self.handle(*args, **options)
  File "/home/chonnakan_r/myuniverse/places/management/commands/repair_data.py", line 73, in handle
    print p['name']
UnicodeEncodeError: 'ascii' codec can't encode characters in position 0-3: ordinal not in range(128)
10
Traceback (most recent call last):
  File "./manage.py", line 10, in <module>
    execute_from_command_line(sys.argv)
  File "/usr/local/lib/python2.7/dist-packages/django/core/management/__init__.py", line 353, in execute_from_command_line
    utility.execute()
  File "/usr/local/lib/python2.7/dist-packages/django/core/management/__init__.py", line 345, in execute
    self.fetch_command(subcommand).run_from_argv(self.argv)
  File "/usr/local/lib/python2.7/dist-packages/django/core/management/base.py", line 348, in run_from_argv
    self.execute(*args, **cmd_options)
  File "/usr/local/lib/python2.7/dist-packages/django/core/management/base.py", line 399, in execute
    output = self.handle(*args, **options)
  File "/home/chonnakan_r/myuniverse/places/management/commands/repair_data.py", line 73, in handle
    print p['name']
UnicodeEncodeError: 'ascii' codec can't encode characters in position 0-3: ordinal not in range(128)
